Workbook

Sheet Tank Calculator
A1: Inputs | G1: Calculated / Derived from Sounding Table
A2: Analog_mA | B2: Sensor_Min_bar | C2: Sensor_Max_bar | D2: Density | E2: Dead_Volume | F2: Tank_Height | G2: Level_m | H2: Interp_Volume_m3 | I2: Final_Volume_m3 | J2: Litres | K2: Tonnage | L2: Level_%
A3: 4 | B3: 0 | C3: 0.3 | D3: 824 | E3: 0.03 | F3: 2.03 | G3: =MIN(F3,MAX(0,((A3-4)/16*(C3-B3)+B3)*100000/(D3*9.81))) -> 0 | H3: {=INDEX('Sounding Table'!B:B,MATCH(G3,'Sounding Table'!A:A,1))+(G3-INDEX('Sounding Table'!A:A,MATCH(G3,'Sounding Table'!A:A,1)))*(INDEX('Sounding Table'!B:B,MATCH(G3,'Sounding Table'!A:A,1)+1)-INDEX('Sounding Table'!B:B,MATCH(G3,'Sounding Table'!A:A,1)))/(INDEX('Sounding Table'!A:A,MATCH(G3,'Sounding Table'!A:A,1)+1)-INDEX('Sounding Table'!A:A,MATCH(G3,'Sounding Table'!A:A,1)))} -> 0.03 | I3: =H3+E3 -> 0.06 | J3: =I3*1000 -> 60 | K3: =I3*D3/1000 -> 0.04944 | L3: =MIN(100,MAX(0,(G3/F3)*100)) -> 0 | N3: data from Wehark
A4: 4.5 | B4: 0 | C4: 0.3 | D4: 824 | E4: 0.03 | F4: 2.03 | G4: =MIN(F4,MAX(0,((A4-4)/16*(C4-B4)+B4)*100000/(D4*9.81))) -> 0.11597785 | H4: {=INDEX('Sounding Table'!B:B,MATCH(G4,'Sounding Table'!A:A,1))+(G4-INDEX('Sounding Table'!A:A,MATCH(G4,'Sounding Table'!A:A,1)))*(INDEX('Sounding Table'!B:B,MATCH(G4,'Sounding Table'!A:A,1)+1)-INDEX('Sounding Table'!B:B,MATCH(G4,'Sounding Table'!A:A,1)))/(INDEX('Sounding Table'!A:A,MATCH(G4,'Sounding Table'!A:A,1)+1)-INDEX('Sounding Table'!A:A,MATCH(G4,'Sounding Table'!A:A,1)))} -> 0.3139114 | I4: =H4+E4 -> 0.3439114 | J4: =I4*1000 -> 343.9114 | K4: =I4*D4/1000 -> 0.283383 | L4: =MIN(100,MAX(0,(G4/F4)*100)) -> 5.7131946 | N4: Sensor output | O4: Height | P4: Volume | Q4: Liters | R4: Tonnage(t) | S4: Percentage
A5: 5 | B5: 0 | C5: 0.3 | D5: 824 | E5: 0.03 | F5: 2.03 | G5: =MIN(F5,MAX(0,((A5-4)/16*(C5-B5)+B5)*100000/(D5*9.81))) -> 0.2319557 | H5: {=INDEX('Sounding Table'!B:B,MATCH(G5,'Sounding Table'!A:A,1))+(G5-INDEX('Sounding Table'!A:A,MATCH(G5,'Sounding Table'!A:A,1)))*(INDEX('Sounding Table'!B:B,MATCH(G5,'Sounding Table'!A:A,1)+1)-INDEX('Sounding Table'!B:B,MATCH(G5,'Sounding Table'!A:A,1)))/(INDEX('Sounding Table'!A:A,MATCH(G5,'Sounding Table'!A:A,1)+1)-INDEX('Sounding Table'!A:A,MATCH(G5,'Sounding Table'!A:A,1)))} -> 0.93173421 | I5: =H5+E5 -> 0.96173421 | J5: =I5*1000 -> 961.73421 | K5: =I5*D5/1000 -> 0.79246899 | L5: =MIN(100,MAX(0,(G5/F5)*100)) -> 11.426389 | N5: (mA) | O5: (m) | P5: (m3) | Q5: (L) | R5: (T) | S5: (%)
A6: 5.5 | B6: 0 | C6: 0.3 | D6: 824 | E6: 0.03 | F6: 2.03 | G6: =MIN(F6,MAX(0,((A6-4)/16*(C6-B6)+B6)*100000/(D6*9.81))) -> 0.34793355 | H6: {=INDEX('Sounding Table'!B:B,MATCH(G6,'Sounding Table'!A:A,1))+(G6-INDEX('Sounding Table'!A:A,MATCH(G6,'Sounding Table'!A:A,1)))*(INDEX('Sounding Table'!B:B,MATCH(G6,'Sounding Table'!A:A,1)+1)-INDEX('Sounding Table'!B:B,MATCH(G6,'Sounding Table'!A:A,1)))/(INDEX('Sounding Table'!A:A,MATCH(G6,'Sounding Table'!A:A,1)+1)-INDEX('Sounding Table'!A:A,MATCH(G6,'Sounding Table'!A:A,1)))} -> 1.7076013 | I6: =H6+E6 -> 1.7376013 | J6: =I6*1000 -> 1737.6013 | K6: =I6*D6/1000 -> 1.4317835 | L6: =MIN(100,MAX(0,(G6/F6)*100)) -> 17.139584 | N6: 4 | O6: 0 | P6: 0.14 | Q6: 140 | R6: 0.13 | S6: 0
A7: 6 | B7: 0 | C7: 0.3 | D7: 824 | E7: 0.03 | F7: 2.03 | G7: =MIN(F7,MAX(0,((A7-4)/16*(C7-B7)+B7)*100000/(D7*9.81))) -> 0.4639114 | H7: {=INDEX('Sounding Table'!B:B,MATCH(G7,'Sounding Table'!A:A,1))+(G7-INDEX('Sounding Table'!A:A,MATCH(G7,'Sounding Table'!A:A,1)))*(INDEX('Sounding Table'!B:B,MATCH(G7,'Sounding Table'!A:A,1)+1)-INDEX('Sounding Table'!B:B,MATCH(G7,'Sounding Table'!A:A,1)))/(INDEX('Sounding Table'!A:A,MATCH(G7,'Sounding Table'!A:A,1)+1)-INDEX('Sounding Table'!A:A,MATCH(G7,'Sounding Table'!A:A,1)))} -> 2.4934684 | I7: =H7+E7 -> 2.5234684 | J7: =I7*1000 -> 2523.4684 | K7: =I7*D7/1000 -> 2.079338 | L7: =MIN(100,MAX(0,(G7/F7)*100)) -> 22.852779 | N7: 4.5 | O7: 0.101 | P7: 0.322 | Q7: 322.38 | R7: 0.31 | S7: 4.67
A8: 6.5 | B8: 0 | C8: 0.3 | D8: 824 | E8: 0.03 | F8: 2.03 | G8: =MIN(F8,MAX(0,((A8-4)/16*(C8-B8)+B8)*100000/(D8*9.81))) -> 0.57988926 | H8: {=INDEX('Sounding Table'!B:B,MATCH(G8,'Sounding Table'!A:A,1))+(G8-INDEX('Sounding Table'!A:A,MATCH(G8,'Sounding Table'!A:A,1)))*(INDEX('Sounding Table'!B:B,MATCH(G8,'Sounding Table'!A:A,1)+1)-INDEX('Sounding Table'!B:B,MATCH(G8,'Sounding Table'!A:A,1)))/(INDEX('Sounding Table'!A:A,MATCH(G8,'Sounding Table'!A:A,1)+1)-INDEX('Sounding Table'!A:A,MATCH(G8,'Sounding Table'!A:A,1)))} -> 3.279114 | I8: =H8+E8 -> 3.309114 | J8: =I8*1000 -> 3309.114 | K8: =I8*D8/1000 -> 2.72671 | L8: =MIN(100,MAX(0,(G8/F8)*100)) -> 28.565973 | N8: 5 | O8: 0.201 | P8: 0.615 | Q8: 614.76 | R8: 0.58 | S8: 9.35
A9: 7 | B9: 0 | C9: 0.3 | D9: 824 | E9: 0.03 | F9: 2.03 | G9: =MIN(F9,MAX(0,((A9-4)/16*(C9-B9)+B9)*100000/(D9*9.81))) -> 0.69586711 | H9: {=INDEX('Sounding Table'!B:B,MATCH(G9,'Sounding Table'!A:A,1))+(G9-INDEX('Sounding Table'!A:A,MATCH(G9,'Sounding Table'!A:A,1)))*(INDEX('Sounding Table'!B:B,MATCH(G9,'Sounding Table'!A:A,1)+1)-INDEX('Sounding Table'!B:B,MATCH(G9,'Sounding Table'!A:A,1)))/(INDEX('Sounding Table'!A:A,MATCH(G9,'Sounding Table'!A:A,1)+1)-INDEX('Sounding Table'!A:A,MATCH(G9,'Sounding Table'!A:A,1)))} -> 4.0569368 | I9: =H9+E9 -> 4.0869368 | J9: =I9*1000 -> 4086.9368 | K9: =I9*D9/1000 -> 3.367636 | L9: =MIN(100,MAX(0,(G9/F9)*100)) -> 34.279168 | N9: 6 | O9: 0.402 | P9: 1.49 | Q9: 1489.53 | R9: 1.42 | S9: 18.7
A10: 7.5 | B10: 0 | C10: 0.3 | D10: 824 | E10: 0.03 | F10: 2.03 | G10: =MIN(F10,MAX(0,((A10-4)/16*(C10-B10)+B10)*100000/(D10*9.81))) -> 0.81184496 | H10: {=INDEX('Sounding Table'!B:B,MATCH(G10,'Sounding Table'!A:A,1))+(G10-INDEX('Sounding Table'!A:A,MATCH(G10,'Sounding Table'!A:A,1)))*(INDEX('Sounding Table'!B:B,MATCH(G10,'Sounding Table'!A:A,1)+1)-INDEX('Sounding Table'!B:B,MATCH(G10,'Sounding Table'!A:A,1)))/(INDEX('Sounding Table'!A:A,MATCH(G10,'Sounding Table'!A:A,1)+1)-INDEX('Sounding Table'!A:A,MATCH(G10,'Sounding Table'!A:A,1)))} -> 4.8410697 | I10: =H10+E10 -> 4.8710697 | J10: =I10*1000 -> 4871.0697 | K10: =I10*D10/1000 -> 4.0137615 | L10: =MIN(100,MAX(0,(G10/F10)*100)) -> 39.992362 | N10: 7 | O10: 0.604 | P10: 2.661 | Q10: 2661.44 | R10: 2.53 | S10: 28.05
A11: 8 | B11: 0 | C11: 0.3 | D11: 824 | E11: 0.03 | F11: 2.03 | G11: =MIN(F11,MAX(0,((A11-4)/16*(C11-B11)+B11)*100000/(D11*9.81))) -> 0.92782281 | H11: {=INDEX('Sounding Table'!B:B,MATCH(G11,'Sounding Table'!A:A,1))+(G11-INDEX('Sounding Table'!A:A,MATCH(G11,'Sounding Table'!A:A,1)))*(INDEX('Sounding Table'!B:B,MATCH(G11,'Sounding Table'!A:A,1)+1)-INDEX('Sounding Table'!B:B,MATCH(G11,'Sounding Table'!A:A,1)))/(INDEX('Sounding Table'!A:A,MATCH(G11,'Sounding Table'!A:A,1)+1)-INDEX('Sounding Table'!A:A,MATCH(G11,'Sounding Table'!A:A,1)))} -> 5.6225825 | I11: =H11+E11 -> 5.6525825 | J11: =I11*1000 -> 5652.5825 | K11: =I11*D11/1000 -> 4.657728 | L11: =MIN(100,MAX(0,(G11/F11)*100)) -> 45.705557 | N11: 8 | O11: 0.805 | P11: 3.938 | Q11: 3938.11 | R11: 3.74 | S11: 37.4
A12: 8.5 | B12: 0 | C12: 0.3 | D12: 824 | E12: 0.03 | F12: 2.03 | G12: =MIN(F12,MAX(0,((A12-4)/16*(C12-B12)+B12)*100000/(D12*9.81))) -> 1.0438007 | H12: {=INDEX('Sounding Table'!B:B,MATCH(G12,'Sounding Table'!A:A,1))+(G12-INDEX('Sounding Table'!A:A,MATCH(G12,'Sounding Table'!A:A,1)))*(INDEX('Sounding Table'!B:B,MATCH(G12,'Sounding Table'!A:A,1)+1)-INDEX('Sounding Table'!B:B,MATCH(G12,'Sounding Table'!A:A,1)))/(INDEX('Sounding Table'!A:A,MATCH(G12,'Sounding Table'!A:A,1)+1)-INDEX('Sounding Table'!A:A,MATCH(G12,'Sounding Table'!A:A,1)))} -> 6.402804 | I12: =H12+E12 -> 6.432804 | J12: =I12*1000 -> 6432.804 | K12: =I12*D12/1000 -> 5.3006305 | L12: =MIN(100,MAX(0,(G12/F12)*100)) -> 51.418752 | N12: 9 | O12: 1.066 | P12: 5.216 | Q12: 5215.73 | R12: 4.95 | S12: 46.75
A13: 9 | B13: 0 | C13: 0.3 | D13: 824 | E13: 0.03 | F13: 2.03 | G13: =MIN(F13,MAX(0,((A13-4)/16*(C13-B13)+B13)*100000/(D13*9.81))) -> 1.1597785 | H13: {=INDEX('Sounding Table'!B:B,MATCH(G13,'Sounding Table'!A:A,1))+(G13-INDEX('Sounding Table'!A:A,MATCH(G13,'Sounding Table'!A:A,1)))*(INDEX('Sounding Table'!B:B,MATCH(G13,'Sounding Table'!A:A,1)+1)-INDEX('Sounding Table'!B:B,MATCH(G13,'Sounding Table'!A:A,1)))/(INDEX('Sounding Table'!A:A,MATCH(G13,'Sounding Table'!A:A,1)+1)-INDEX('Sounding Table'!A:A,MATCH(G13,'Sounding Table'!A:A,1)))} -> 7.1886711 | I13: =H13+E13 -> 7.2186711 | J13: =I13*1000 -> 7218.6711 | K13: =I13*D13/1000 -> 5.948185 | L13: =MIN(100,MAX(0,(G13/F13)*100)) -> 57.131946 | N13: 10 | O13: 1.207 | P13: 6.497 | Q13: 6497.17 | R13: 6.17 | S13: 56.09
A14: 9.5 | B14: 0 | C14: 0.3 | D14: 824 | E14: 0.03 | F14: 2.03 | G14: =MIN(F14,MAX(0,((A14-4)/16*(C14-B14)+B14)*100000/(D14*9.81))) -> 1.2757564 | H14: {=INDEX('Sounding Table'!B:B,MATCH(G14,'Sounding Table'!A:A,1))+(G14-INDEX('Sounding Table'!A:A,MATCH(G14,'Sounding Table'!A:A,1)))*(INDEX('Sounding Table'!B:B,MATCH(G14,'Sounding Table'!A:A,1)+1)-INDEX('Sounding Table'!B:B,MATCH(G14,'Sounding Table'!A:A,1)))/(INDEX('Sounding Table'!A:A,MATCH(G14,'Sounding Table'!A:A,1)+1)-INDEX('Sounding Table'!A:A,MATCH(G14,'Sounding Table'!A:A,1)))} -> 7.9745382 | I14: =H14+E14 -> 8.0045382 | J14: =I14*1000 -> 8004.5382 | K14: =I14*D14/1000 -> 6.5957394 | L14: =MIN(100,MAX(0,(G14/F14)*100)) -> 62.845141 | N14: 12 | O14: 1.61 | P14: 9.057 | Q14: 9057.17 | R14: 8.6 | S14: 74.79
A15: 10 | B15: 0 | C15: 0.3 | D15: 824 | E15: 0.03 | F15: 2.03 | G15: =MIN(F15,MAX(0,((A15-4)/16*(C15-B15)+B15)*100000/(D15*9.81))) -> 1.3917342 | H15: {=INDEX('Sounding Table'!B:B,MATCH(G15,'Sounding Table'!A:A,1))+(G15-INDEX('Sounding Table'!A:A,MATCH(G15,'Sounding Table'!A:A,1)))*(INDEX('Sounding Table'!B:B,MATCH(G15,'Sounding Table'!A:A,1)+1)-INDEX('Sounding Table'!B:B,MATCH(G15,'Sounding Table'!A:A,1)))/(INDEX('Sounding Table'!A:A,MATCH(G15,'Sounding Table'!A:A,1)+1)-INDEX('Sounding Table'!A:A,MATCH(G15,'Sounding Table'!A:A,1)))} -> 8.7538737 | I15: =H15+E15 -> 8.7838737 | J15: =I15*1000 -> 8783.8737 | K15: =I15*D15/1000 -> 7.2379119 | L15: =MIN(100,MAX(0,(G15/F15)*100)) -> 68.558336 | N15: 14 | O15: 2.012 | P15: 11.621 | Q15: 11621.46 | R15: 11.04 | S15: 93.49
A16: 10.5 | B16: 0 | C16: 0.3 | D16: 824 | E16: 0.03 | F16: 2.03 | G16: =MIN(F16,MAX(0,((A16-4)/16*(C16-B16)+B16)*100000/(D16*9.81))) -> 1.5077121 | H16: {=INDEX('Sounding Table'!B:B,MATCH(G16,'Sounding Table'!A:A,1))+(G16-INDEX('Sounding Table'!A:A,MATCH(G16,'Sounding Table'!A:A,1)))*(INDEX('Sounding Table'!B:B,MATCH(G16,'Sounding Table'!A:A,1)+1)-INDEX('Sounding Table'!B:B,MATCH(G16,'Sounding Table'!A:A,1)))/(INDEX('Sounding Table'!A:A,MATCH(G16,'Sounding Table'!A:A,1)+1)-INDEX('Sounding Table'!A:A,MATCH(G16,'Sounding Table'!A:A,1)))} -> 9.5362724 | I16: =H16+E16 -> 9.5662724 | J16: =I16*1000 -> 9566.2724 | K16: =I16*D16/1000 -> 7.8826084 | L16: =MIN(100,MAX(0,(G16/F16)*100)) -> 74.27153 | N16: 15 | O16: 2.152 | P16: 12.5 | Q16: 12520 | R16: 11.89 | S16: 100
A17: 11 | B17: 0 | C17: 0.3 | D17: 824 | E17: 0.03 | F17: 2.03 | G17: =MIN(F17,MAX(0,((A17-4)/16*(C17-B17)+B17)*100000/(D17*9.81))) -> 1.6236899 | H17: {=INDEX('Sounding Table'!B:B,MATCH(G17,'Sounding Table'!A:A,1))+(G17-INDEX('Sounding Table'!A:A,MATCH(G17,'Sounding Table'!A:A,1)))*(INDEX('Sounding Table'!B:B,MATCH(G17,'Sounding Table'!A:A,1)+1)-INDEX('Sounding Table'!B:B,MATCH(G17,'Sounding Table'!A:A,1)))/(INDEX('Sounding Table'!A:A,MATCH(G17,'Sounding Table'!A:A,1)+1)-INDEX('Sounding Table'!A:A,MATCH(G17,'Sounding Table'!A:A,1)))} -> 10.322139 | I17: =H17+E17 -> 10.352139 | J17: =I17*1000 -> 10352.139 | K17: =I17*D17/1000 -> 8.5301629 | L17: =MIN(100,MAX(0,(G17/F17)*100)) -> 79.984725
A18: 11.5 | B18: 0 | C18: 0.3 | D18: 824 | E18: 0.03 | F18: 2.03 | G18: =MIN(F18,MAX(0,((A18-4)/16*(C18-B18)+B18)*100000/(D18*9.81))) -> 1.7396678 | H18: {=INDEX('Sounding Table'!B:B,MATCH(G18,'Sounding Table'!A:A,1))+(G18-INDEX('Sounding Table'!A:A,MATCH(G18,'Sounding Table'!A:A,1)))*(INDEX('Sounding Table'!B:B,MATCH(G18,'Sounding Table'!A:A,1)+1)-INDEX('Sounding Table'!B:B,MATCH(G18,'Sounding Table'!A:A,1)))/(INDEX('Sounding Table'!A:A,MATCH(G18,'Sounding Table'!A:A,1)+1)-INDEX('Sounding Table'!A:A,MATCH(G18,'Sounding Table'!A:A,1)))} -> 11.107342 | I18: =H18+E18 -> 11.137342 | J18: =I18*1000 -> 11137.342 | K18: =I18*D18/1000 -> 9.1771699 | L18: =MIN(100,MAX(0,(G18/F18)*100)) -> 85.697919
A19: 12 | B19: 0 | C19: 0.3 | D19: 824 | E19: 0.03 | F19: 2.03 | G19: =MIN(F19,MAX(0,((A19-4)/16*(C19-B19)+B19)*100000/(D19*9.81))) -> 1.8556456 | H19: {=INDEX('Sounding Table'!B:B,MATCH(G19,'Sounding Table'!A:A,1))+(G19-INDEX('Sounding Table'!A:A,MATCH(G19,'Sounding Table'!A:A,1)))*(INDEX('Sounding Table'!B:B,MATCH(G19,'Sounding Table'!A:A,1)+1)-INDEX('Sounding Table'!B:B,MATCH(G19,'Sounding Table'!A:A,1)))/(INDEX('Sounding Table'!A:A,MATCH(G19,'Sounding Table'!A:A,1)+1)-INDEX('Sounding Table'!A:A,MATCH(G19,'Sounding Table'!A:A,1)))} -> 11.885165 | I19: =H19+E19 -> 11.915165 | J19: =I19*1000 -> 11915.165 | K19: =I19*D19/1000 -> 9.8180959 | L19: =MIN(100,MAX(0,(G19/F19)*100)) -> 91.411114
A20: 12.5 | B20: 0 | C20: 0.3 | D20: 824 | E20: 0.03 | F20: 2.03 | G20: =MIN(F20,MAX(0,((A20-4)/16*(C20-B20)+B20)*100000/(D20*9.81))) -> 1.9716235 | H20: {=INDEX('Sounding Table'!B:B,MATCH(G20,'Sounding Table'!A:A,1))+(G20-INDEX('Sounding Table'!A:A,MATCH(G20,'Sounding Table'!A:A,1)))*(INDEX('Sounding Table'!B:B,MATCH(G20,'Sounding Table'!A:A,1)+1)-INDEX('Sounding Table'!B:B,MATCH(G20,'Sounding Table'!A:A,1)))/(INDEX('Sounding Table'!A:A,MATCH(G20,'Sounding Table'!A:A,1)+1)-INDEX('Sounding Table'!A:A,MATCH(G20,'Sounding Table'!A:A,1)))} -> 12.669741 | I20: =H20+E20 -> 12.699741 | J20: =I20*1000 -> 12699.741 | K20: =I20*D20/1000 -> 10.464586 | L20: =MIN(100,MAX(0,(G20/F20)*100)) -> 97.124309 | N20: TANKS | O20: Min_bar | P20: Max_bar | Q20: DENSITY | R20: Dead_Volume | S20: Tank_Height
A21: 13 | B21: 0 | C21: 0.3 | D21: 824 | E21: 0.03 | F21: 2.03 | G21: =MIN(F21,MAX(0,((A21-4)/16*(C21-B21)+B21)*100000/(D21*9.81))) -> 2.03 | H21: {=INDEX('Sounding Table'!B:B,MATCH(G21,'Sounding Table'!A:A,1))+(G21-INDEX('Sounding Table'!A:A,MATCH(G21,'Sounding Table'!A:A,1)))*(INDEX('Sounding Table'!B:B,MATCH(G21,'Sounding Table'!A:A,1)+1)-INDEX('Sounding Table'!B:B,MATCH(G21,'Sounding Table'!A:A,1)))/(INDEX('Sounding Table'!A:A,MATCH(G21,'Sounding Table'!A:A,1)+1)-INDEX('Sounding Table'!A:A,MATCH(G21,'Sounding Table'!A:A,1)))} -> 13.06 | I21: =H21+E21 -> 13.09 | J21: =I21*1000 -> 13090 | K21: =I21*D21/1000 -> 10.78616 | L21: =MIN(100,MAX(0,(G21/F21)*100)) -> 100 | N21: DIRTY OIL TANK | O21: 0 | P21: 0.2 | Q21: 824 | R21: 0.01 | S21: 0.886
A22: 13.5 | B22: 0 | C22: 0.3 | D22: 824 | E22: 0.03 | F22: 2.03 | G22: =MIN(F22,MAX(0,((A22-4)/16*(C22-B22)+B22)*100000/(D22*9.81))) -> 2.03 | H22: {=INDEX('Sounding Table'!B:B,MATCH(G22,'Sounding Table'!A:A,1))+(G22-INDEX('Sounding Table'!A:A,MATCH(G22,'Sounding Table'!A:A,1)))*(INDEX('Sounding Table'!B:B,MATCH(G22,'Sounding Table'!A:A,1)+1)-INDEX('Sounding Table'!B:B,MATCH(G22,'Sounding Table'!A:A,1)))/(INDEX('Sounding Table'!A:A,MATCH(G22,'Sounding Table'!A:A,1)+1)-INDEX('Sounding Table'!A:A,MATCH(G22,'Sounding Table'!A:A,1)))} -> 13.06 | I22: =H22+E22 -> 13.09 | J22: =I22*1000 -> 13090 | K22: =I22*D22/1000 -> 10.78616 | L22: =MIN(100,MAX(0,(G22/F22)*100)) -> 100 | N22: FO RU TANK 1 | O22: 0 | P22: 0.2 | Q22: 824 | R22: 0.03 | S22: 2.075
A23: 14 | B23: 0 | C23: 0.3 | D23: 824 | E23: 0.03 | F23: 2.03 | G23: =MIN(F23,MAX(0,((A23-4)/16*(C23-B23)+B23)*100000/(D23*9.81))) -> 2.03 | H23: {=INDEX('Sounding Table'!B:B,MATCH(G23,'Sounding Table'!A:A,1))+(G23-INDEX('Sounding Table'!A:A,MATCH(G23,'Sounding Table'!A:A,1)))*(INDEX('Sounding Table'!B:B,MATCH(G23,'Sounding Table'!A:A,1)+1)-INDEX('Sounding Table'!B:B,MATCH(G23,'Sounding Table'!A:A,1)))/(INDEX('Sounding Table'!A:A,MATCH(G23,'Sounding Table'!A:A,1)+1)-INDEX('Sounding Table'!A:A,MATCH(G23,'Sounding Table'!A:A,1)))} -> 13.06 | I23: =H23+E23 -> 13.09 | J23: =I23*1000 -> 13090 | K23: =I23*D23/1000 -> 10.78616 | L23: =MIN(100,MAX(0,(G23/F23)*100)) -> 100 | N23: FO RU TANK 2 | O23: 0 | P23: 0.2 | Q23: 824 | R23: 0.03 | S23: 2.076
A24: 14.5 | B24: 0 | C24: 0.3 | D24: 824 | E24: 0.03 | F24: 2.03 | G24: =MIN(F24,MAX(0,((A24-4)/16*(C24-B24)+B24)*100000/(D24*9.81))) -> 2.03 | H24: {=INDEX('Sounding Table'!B:B,MATCH(G24,'Sounding Table'!A:A,1))+(G24-INDEX('Sounding Table'!A:A,MATCH(G24,'Sounding Table'!A:A,1)))*(INDEX('Sounding Table'!B:B,MATCH(G24,'Sounding Table'!A:A,1)+1)-INDEX('Sounding Table'!B:B,MATCH(G24,'Sounding Table'!A:A,1)))/(INDEX('Sounding Table'!A:A,MATCH(G24,'Sounding Table'!A:A,1)+1)-INDEX('Sounding Table'!A:A,MATCH(G24,'Sounding Table'!A:A,1)))} -> 13.06 | I24: =H24+E24 -> 13.09 | J24: =I24*1000 -> 13090 | K24: =I24*D24/1000 -> 10.78616 | L24: =MIN(100,MAX(0,(G24/F24)*100)) -> 100 | N24: FO RU TANK 3 | O24: 0 | P24: 0.2 | Q24: 824 | R24: 0.04 | S24: 2.075
A25: 15 | B25: 0 | C25: 0.3 | D25: 824 | E25: 0.03 | F25: 2.03 | G25: =MIN(F25,MAX(0,((A25-4)/16*(C25-B25)+B25)*100000/(D25*9.81))) -> 2.03 | H25: =INDEX('Sounding Table'!B:B,MATCH(G25,'Sounding Table'!A:A,1))+(G25-INDEX('Sounding Table'!A:A,MATCH(G25,'Sounding Table'!A:A,1)))*(INDEX('Sounding Table'!B:B,MATCH(G25,'Sounding Table'!A:A,1)+1)-INDEX('Sounding Table'!B:B,MATCH(G25,'Sounding Table'!A:A,1)))/(INDEX('Sounding Table'!A:A,MATCH(G25,'Sounding Table'!A:A,1)+1)-INDEX('Sounding Table'!A:A,MATCH(G25,'Sounding Table'!A:A,1))) -> 13.06 | I25: =H25+E25 -> 13.09 | J25: =I25*1000 -> 13090 | K25: =I25*D25/1000 -> 10.78616 | L25: =MIN(100,MAX(0,(G25/F25)*100)) -> 100 | N25: FO RU TANK 4 | O25: 0 | P25: 0.2 | Q25: 824 | R25: 0.04 | S25: 2.075
A26: 15.5 | B26: 0 | C26: 0.3 | D26: 824 | E26: 0.03 | F26: 2.03 | G26: =MIN(F26,MAX(0,((A26-4)/16*(C26-B26)+B26)*100000/(D26*9.81))) -> 2.03 | H26: =INDEX('Sounding Table'!B:B,MATCH(G26,'Sounding Table'!A:A,1))+(G26-INDEX('Sounding Table'!A:A,MATCH(G26,'Sounding Table'!A:A,1)))*(INDEX('Sounding Table'!B:B,MATCH(G26,'Sounding Table'!A:A,1)+1)-INDEX('Sounding Table'!B:B,MATCH(G26,'Sounding Table'!A:A,1)))/(INDEX('Sounding Table'!A:A,MATCH(G26,'Sounding Table'!A:A,1)+1)-INDEX('Sounding Table'!A:A,MATCH(G26,'Sounding Table'!A:A,1))) -> 13.06 | I26: =H26+E26 -> 13.09 | J26: =I26*1000 -> 13090 | K26: =I26*D26/1000 -> 10.78616 | L26: =MIN(100,MAX(0,(G26/F26)*100)) -> 100 | N26: FRESH WATER TANK | O26: 0 | P26: 0.3 | Q26: 1000 | R26: 0.07 | S26: 2.152
A27: 16 | B27: 0 | C27: 0.3 | D27: 824 | E27: 0.03 | F27: 2.03 | G27: =MIN(F27,MAX(0,((A27-4)/16*(C27-B27)+B27)*100000/(D27*9.81))) -> 2.03 | H27: =INDEX('Sounding Table'!B:B,MATCH(G27,'Sounding Table'!A:A,1))+(G27-INDEX('Sounding Table'!A:A,MATCH(G27,'Sounding Table'!A:A,1)))*(INDEX('Sounding Table'!B:B,MATCH(G27,'Sounding Table'!A:A,1)+1)-INDEX('Sounding Table'!B:B,MATCH(G27,'Sounding Table'!A:A,1)))/(INDEX('Sounding Table'!A:A,MATCH(G27,'Sounding Table'!A:A,1)+1)-INDEX('Sounding Table'!A:A,MATCH(G27,'Sounding Table'!A:A,1))) -> 13.06 | I27: =H27+E27 -> 13.09 | J27: =I27*1000 -> 13090 | K27: =I27*D27/1000 -> 10.78616 | L27: =MIN(100,MAX(0,(G27/F27)*100)) -> 100 | N27: FUEL OIL TANK 1 | O27: 0 | P27: 0.3 | Q27: 824 | R27: 0.03 | S27: 2.03
A28: 16.5 | B28: 0 | C28: 0.3 | D28: 824 | E28: 0.03 | F28: 2.03 | G28: =MIN(F28,MAX(0,((A28-4)/16*(C28-B28)+B28)*100000/(D28*9.81))) -> 2.03 | H28: =INDEX('Sounding Table'!B:B,MATCH(G28,'Sounding Table'!A:A,1))+(G28-INDEX('Sounding Table'!A:A,MATCH(G28,'Sounding Table'!A:A,1)))*(INDEX('Sounding Table'!B:B,MATCH(G28,'Sounding Table'!A:A,1)+1)-INDEX('Sounding Table'!B:B,MATCH(G28,'Sounding Table'!A:A,1)))/(INDEX('Sounding Table'!A:A,MATCH(G28,'Sounding Table'!A:A,1)+1)-INDEX('Sounding Table'!A:A,MATCH(G28,'Sounding Table'!A:A,1))) -> 13.06 | I28: =H28+E28 -> 13.09 | J28: =I28*1000 -> 13090 | K28: =I28*D28/1000 -> 10.78616 | L28: =MIN(100,MAX(0,(G28/F28)*100)) -> 100 | N28: FUEL OIL TANK 2 | O28: 0 | P28: 0.3 | Q28: 824 | R28: 0 | S28: 1.98
A29: 17 | B29: 0 | C29: 0.3 | D29: 824 | E29: 0.03 | F29: 2.03 | G29: =MIN(F29,MAX(0,((A29-4)/16*(C29-B29)+B29)*100000/(D29*9.81))) -> 2.03 | H29: =INDEX('Sounding Table'!B:B,MATCH(G29,'Sounding Table'!A:A,1))+(G29-INDEX('Sounding Table'!A:A,MATCH(G29,'Sounding Table'!A:A,1)))*(INDEX('Sounding Table'!B:B,MATCH(G29,'Sounding Table'!A:A,1)+1)-INDEX('Sounding Table'!B:B,MATCH(G29,'Sounding Table'!A:A,1)))/(INDEX('Sounding Table'!A:A,MATCH(G29,'Sounding Table'!A:A,1)+1)-INDEX('Sounding Table'!A:A,MATCH(G29,'Sounding Table'!A:A,1))) -> 13.06 | I29: =H29+E29 -> 13.09 | J29: =I29*1000 -> 13090 | K29: =I29*D29/1000 -> 10.78616 | L29: =MIN(100,MAX(0,(G29/F29)*100)) -> 100 | N29: FUEL OIL TANK 3 | O29: 0 | P29: 0.2 | Q29: 824 | R29: 0.03 | S29: 0.708
A30: 17.5 | B30: 0 | C30: 0.3 | D30: 824 | E30: 0.03 | F30: 2.03 | G30: =MIN(F30,MAX(0,((A30-4)/16*(C30-B30)+B30)*100000/(D30*9.81))) -> 2.03 | H30: =INDEX('Sounding Table'!B:B,MATCH(G30,'Sounding Table'!A:A,1))+(G30-INDEX('Sounding Table'!A:A,MATCH(G30,'Sounding Table'!A:A,1)))*(INDEX('Sounding Table'!B:B,MATCH(G30,'Sounding Table'!A:A,1)+1)-INDEX('Sounding Table'!B:B,MATCH(G30,'Sounding Table'!A:A,1)))/(INDEX('Sounding Table'!A:A,MATCH(G30,'Sounding Table'!A:A,1)+1)-INDEX('Sounding Table'!A:A,MATCH(G30,'Sounding Table'!A:A,1))) -> 13.06 | I30: =H30+E30 -> 13.09 | J30: =I30*1000 -> 13090 | K30: =I30*D30/1000 -> 10.78616 | L30: =MIN(100,MAX(0,(G30/F30)*100)) -> 100 | N30: GREY WATER TANK | O30: 0 | P30: 0.3 | Q30: 1025 | R30: 0.01 | S30: 2.196
A31: 18 | B31: 0 | C31: 0.3 | D31: 824 | E31: 0.03 | F31: 2.03 | G31: =MIN(F31,MAX(0,((A31-4)/16*(C31-B31)+B31)*100000/(D31*9.81))) -> 2.03 | H31: =INDEX('Sounding Table'!B:B,MATCH(G31,'Sounding Table'!A:A,1))+(G31-INDEX('Sounding Table'!A:A,MATCH(G31,'Sounding Table'!A:A,1)))*(INDEX('Sounding Table'!B:B,MATCH(G31,'Sounding Table'!A:A,1)+1)-INDEX('Sounding Table'!B:B,MATCH(G31,'Sounding Table'!A:A,1)))/(INDEX('Sounding Table'!A:A,MATCH(G31,'Sounding Table'!A:A,1)+1)-INDEX('Sounding Table'!A:A,MATCH(G31,'Sounding Table'!A:A,1))) -> 13.06 | I31: =H31+E31 -> 13.09 | J31: =I31*1000 -> 13090 | K31: =I31*D31/1000 -> 10.78616 | L31: =MIN(100,MAX(0,(G31/F31)*100)) -> 100 | N31: LO_TANK | O31: 0 | P31: 0.2 | Q31: 870 | R31: 0.14 | S31: 0.8
A32: 18.5 | B32: 0 | C32: 0.3 | D32: 824 | E32: 0.03 | F32: 2.03 | G32: =MIN(F32,MAX(0,((A32-4)/16*(C32-B32)+B32)*100000/(D32*9.81))) -> 2.03 | H32: =INDEX('Sounding Table'!B:B,MATCH(G32,'Sounding Table'!A:A,1))+(G32-INDEX('Sounding Table'!A:A,MATCH(G32,'Sounding Table'!A:A,1)))*(INDEX('Sounding Table'!B:B,MATCH(G32,'Sounding Table'!A:A,1)+1)-INDEX('Sounding Table'!B:B,MATCH(G32,'Sounding Table'!A:A,1)))/(INDEX('Sounding Table'!A:A,MATCH(G32,'Sounding Table'!A:A,1)+1)-INDEX('Sounding Table'!A:A,MATCH(G32,'Sounding Table'!A:A,1))) -> 13.06 | I32: =H32+E32 -> 13.09 | J32: =I32*1000 -> 13090 | K32: =I32*D32/1000 -> 10.78616 | L32: =MIN(100,MAX(0,(G32/F32)*100)) -> 100 | N32: BILGE OIL TANK | O32: 0 | P32: 0.2 | Q32: 824 | R32: 0.01 | S32: 0.896
A33: 19 | B33: 0 | C33: 0.3 | D33: 824 | E33: 0.03 | F33: 2.03 | G33: =MIN(F33,MAX(0,((A33-4)/16*(C33-B33)+B33)*100000/(D33*9.81))) -> 2.03 | H33: =INDEX('Sounding Table'!B:B,MATCH(G33,'Sounding Table'!A:A,1))+(G33-INDEX('Sounding Table'!A:A,MATCH(G33,'Sounding Table'!A:A,1)))*(INDEX('Sounding Table'!B:B,MATCH(G33,'Sounding Table'!A:A,1)+1)-INDEX('Sounding Table'!B:B,MATCH(G33,'Sounding Table'!A:A,1)))/(INDEX('Sounding Table'!A:A,MATCH(G33,'Sounding Table'!A:A,1)+1)-INDEX('Sounding Table'!A:A,MATCH(G33,'Sounding Table'!A:A,1))) -> 13.06 | I33: =H33+E33 -> 13.09 | J33: =I33*1000 -> 13090 | K33: =I33*D33/1000 -> 10.78616 | L33: =MIN(100,MAX(0,(G33/F33)*100)) -> 100
A34: 19.5 | B34: 0 | C34: 0.3 | D34: 824 | E34: 0.03 | F34: 2.03 | G34: =MIN(F34,MAX(0,((A34-4)/16*(C34-B34)+B34)*100000/(D34*9.81))) -> 2.03 | H34: =INDEX('Sounding Table'!B:B,MATCH(G34,'Sounding Table'!A:A,1))+(G34-INDEX('Sounding Table'!A:A,MATCH(G34,'Sounding Table'!A:A,1)))*(INDEX('Sounding Table'!B:B,MATCH(G34,'Sounding Table'!A:A,1)+1)-INDEX('Sounding Table'!B:B,MATCH(G34,'Sounding Table'!A:A,1)))/(INDEX('Sounding Table'!A:A,MATCH(G34,'Sounding Table'!A:A,1)+1)-INDEX('Sounding Table'!A:A,MATCH(G34,'Sounding Table'!A:A,1))) -> 13.06 | I34: =H34+E34 -> 13.09 | J34: =I34*1000 -> 13090 | K34: =I34*D34/1000 -> 10.78616 | L34: =MIN(100,MAX(0,(G34/F34)*100)) -> 100
A35: 20 | B35: 0 | C35: 0.3 | D35: 824 | E35: 0.03 | F35: 2.03 | G35: =MIN(F35,MAX(0,((A35-4)/16*(C35-B35)+B35)*100000/(D35*9.81))) -> 2.03 | H35: =INDEX('Sounding Table'!B:B,MATCH(G35,'Sounding Table'!A:A,1))+(G35-INDEX('Sounding Table'!A:A,MATCH(G35,'Sounding Table'!A:A,1)))*(INDEX('Sounding Table'!B:B,MATCH(G35,'Sounding Table'!A:A,1)+1)-INDEX('Sounding Table'!B:B,MATCH(G35,'Sounding Table'!A:A,1)))/(INDEX('Sounding Table'!A:A,MATCH(G35,'Sounding Table'!A:A,1)+1)-INDEX('Sounding Table'!A:A,MATCH(G35,'Sounding Table'!A:A,1))) -> 13.06 | I35: =H35+E35 -> 13.09 | J35: =I35*1000 -> 13090 | K35: =I35*D35/1000 -> 10.78616 | L35: =MIN(100,MAX(0,(G35/F35)*100)) -> 100

Sheet Sounding Table
A1: Level_m | B1: Volume_m3 | C1: Weight
A2: 0 | B2: 0.03 | C2: 0.02
A3: 0.005 | B3: 0.03 | C3: 0.03
A4: 0.01 | B4: 0.04 | C4: 0.03
A5: 0.015 | B5: 0.05 | C5: 0.04
A6: 0.02 | B6: 0.05 | C6: 0.05
A7: 0.025 | B7: 0.06 | C7: 0.05
A8: 0.03 | B8: 0.07 | C8: 0.06
A9: 0.035 | B9: 0.08 | C9: 0.07
A10: 0.04 | B10: 0.09 | C10: 0.08
A11: 0.045 | B11: 0.1 | C11: 0.09
A12: 0.05 | B12: 0.11 | C12: 0.1
A13: 0.055 | B13: 0.12 | C13: 0.11
... A409: 2.03 | B409: 13.06 | C409: 11.1

Sheet Sounding Table (2)
A1: Level_m | B1: Volume_m3 | C1: Weight | D1: Correction_factor | F1: Revised Value | H1: Level_m | I1: Volume_m3 | J1: Correction_factor | L1: Level_m | M1: Volume_m3 | AF1: Level_m | AG1: Volume_m3 | AH1: Volume_m3 | AI1: Correction_factor
A2: 0 | B2: 0.03 | C2: 0.02 | D2: =M2-B2 -> 0 | F2: =B2+D2 -> 0.03 | H2: 0 | I2: 0.03 | J2: 0.01 | L2: 0 | M2: =$I$2 + (L2/$H$3) * ($I$3 - $I$2) -> 0.03 | AF2: 0 | AG2: 0.03 | AH2: 0.04 | AI2: =AH2-AG2 -> 0.01
A3: 0.005 | B3: 0.03 | C3: 0.03 | D3: =M3-B3 -> 0.01 | F3: =B3+D3 -> 0.04 | H3: 0.1 | I3: 0.23 | J3: -0.03 | L3: 0.005 | M3: =$I$2 + (L3/$H$3) * ($I$3 - $I$2) -> 0.04 | AF3: 0.1 | AG3: 0.26 | AH3: 0.23 | AI3: =AH3-AG3 -> -0.03
A4: 0.01 | B4: 0.04 | C4: 0.03 | D4: =M4-B4 -> 0.01 | F4: =B4+D4 -> 0.05 | H4: 0.2 | I4: 0.85 | J4: 0.12 | L4: 0.01 | M4: =$I$2 + (L4/$H$3) * ($I$3 - $I$2) -> 0.05 | AF4: 0.2 | AG4: 0.73 | AH4: 0.85 | AI4: =AH4-AG4 -> 0.12
A5: 0.015 | B5: 0.05 | C5: 0.04 | D5: =M5-B5 -> 0.01 | F5: =B5+D5 -> 0.06 | H5: 0.3 | I5: 1.15 | J5: -0.24 | L5: 0.015 | M5: =$I$2 + (L5/$H$3) * ($I$3 - $I$2) -> 0.06 | AF5: 0.3 | AG5: 1.39 | AH5: 1.15 | AI5: =AH5-AG5 -> -0.24
A6: 0.02 | B6: 0.05 | C6: 0.05 | D6: =M6-B6 -> 0.02 | F6: =B6+D6 -> 0.07 | H6: 0.4 | I6: 2 | J6: -0.06 | L6: 0.02 | M6: =$I$2 + (L6/$H$3) * ($I$3 - $I$2) -> 0.07 | AF6: 0.4 | AG6: 2.06 | AH6: 2 | AI6: =AH6-AG6 -> -0.06
A7: 0.025 | B7: 0.06 | C7: 0.05 | D7: =M7-B7 -> 0.02 | F7: =B7+D7 -> 0.08 | H7: 0.5 | I7: 2.5 | J7: -0.24 | L7: 0.025 | M7: =$I$2 + (L7/$H$3) * ($I$3 - $I$2) -> 0.08 | AF7: 0.5 | AG7: 2.74 | AH7: 2.5 | AI7: =AH7-AG7 -> -0.24
A8: 0.03 | B8: 0.07 | C8: 0.06 | D8: =M8-B8 -> 0.02 | F8: =B8+D8 -> 0.09 | H8: 0.6 | I8: 3.23 | J8: -0.18 | L8: 0.03 | M8: =$I$2 + (L8/$H$3) * ($I$3 - $I$2) -> 0.09 | AF8: 0.6 | AG8: 3.41 | AH8: 3.23 | AI8: =AH8-AG8 -> -0.18
A9: 0.035 | B9: 0.08 | C9: 0.07 | D9: =M9-B9 -> 0.02 | F9: =B9+D9 -> 0.1 | H9: 0.7 | I9: 4.25 | J9: 0.16 | L9: 0.035 | M9: =$I$2 + (L9/$H$3) * ($I$3 - $I$2) -> 0.1 | AF9: 0.7 | AG9: 4.09 | AH9: 4.25 | AI9: =AH9-AG9 -> 0.16
A10: 0.04 | B10: 0.09 | C10: 0.08 | D10: =M10-B10 -> 0.02 | F10: =B10+D10 -> 0.11 | H10: 0.8 | I10: 4.9 | J10: 0.14 | L10: 0.04 | M10: =$I$2 + (L10/$H$3) * ($I$3 - $I$2) -> 0.11 | AF10: 0.8 | AG10: 4.76 | AH10: 4.9 | AI10: =AH10-AG10 -> 0.14
A11: 0.045 | B11: 0.1 | C11: 0.09 | D11: =M11-B11 -> 0.02 | F11: =B11+D11 -> 0.12 | H11: 0.9 | I11: 5.25 | J11: -0.19 | L11: 0.045 | M11: =$I$2 + (L11/$H$3) * ($I$3 - $I$2) -> 0.12 | AF11: 0.9 | AG11: 5.44 | AH11: 5.25 | AI11: =AH11-AG11 -> -0.19
A12: 0.05 | B12: 0.11 | C12: 0.1 | D12: =M12-B12 -> 0.02 | F12: =B12+D12 -> 0.13 | H12: 1 | I12: 6 | J12: -0.11 | L12: 0.05 | M12: =$I$2 + (L12/$H$3) * ($I$3 - $I$2) -> 0.13 | AF12: 1 | AG12: 6.11 | AH12: 6 | AI12: =AH12-AG12 -> -0.11
A13: 0.055 | B13: 0.12 | C13: 0.11 | D13: =M13-B13 -> 0.02 | F13: =B13+D13 -> 0.14 | H13: 1.1 | I13: 6.5 | J13: -0.29 | L13: 0.055 | M13: =$I$2 + (L13/$H$3) * ($I$3 - $I$2) -> 0.14 | AF13: 1.1 | AG13: 6.79 | AH13: 6.5 | AI13: =AH13-AG13 -> -0.29
... A22: 0.1 | B22: 0.26 | C22: 0.22 | D22: =M22-B22 -> -0.03 | F22: =B22+D22 -> 0.23 | H22: 2 | I22: 12.5 | J22: -0.36 | L22: 0.1 | M22: =$I$2 + (L22/$H$3) * ($I$3 - $I$2) -> 0.23 | AF22: 2 | AG22: 12.86 | AH22: 12.5 | AI22: =AH22-AG22 -> -0.36
A23: 0.105 | B23: 0.28 | C23: 0.23 | H23: 2.03 | I23: 13 | J23: -0.06 | L23: 0.105 | M23: 0.28 | AF23: 2.03 | AG23: 13.06 | AH23: 13 | AI23: =AH23-AG23 -> -0.06
A24: 0.11 | B24: 0.29 | C24: 0.25 | L24: 0.11 | M24: 0.29
A25: 0.115 | B25: 0.31 | C25: 0.27 | L25: 0.115 | M25: 0.31
A26: 0.12 | B26: 0.33 | C26: 0.28 | L26: 0.12 | M26: 0.33
A27: 0.125 | B27: 0.35 | C27: 0.3 | L27: 0.125 | M27: 0.35
A28: 0.13 | B28: 0.37 | C28: 0.32 | L28: 0.13 | M28: 0.37
A29: 0.135 | B29: 0.4 | C29: 0.34 | L29: 0.135 | M29: 0.4
A30: 0.14 | B30: 0.42 | C30: 0.35 | L30: 0.14 | M30: 0.42
A31: 0.145 | B31: 0.44 | C31: 0.37 | L31: 0.145 | M31: 0.44
A32: 0.15 | B32: 0.46 | C32: 0.39 | L32: 0.15 | M32: 0.46
A33: 0.155 | B33: 0.49 | C33: 0.41 | L33: 0.155 | M33: 0.49
A34: 0.16 | B34: 0.51 | C34: 0.43 | L34: 0.16 | M34: 0.51
A35: 0.165 | B35: 0.54 | C35: 0.46 | L35: 0.165 | M35: 0.54
... A41: 0.195 | B41: 0.7 | C41: 0.59 | L41: 0.195 | M41: 0.7
A42: 0.2 | B42: 0.73 | C42: 0.62 | D42: 0.12 | L42: 0.2 | M42: 0.73
A43: 0.205 | B43: 0.76 | C43: 0.64 | L43: 0.205 | M43: 0.76
A44: 0.21 | B44: 0.79 | C44: 0.67 | L44: 0.21 | M44: 0.79
A45: 0.215 | B45: 0.82 | C45: 0.7 | L45: 0.215 | M45: 0.82
A46: 0.22 | B46: 0.85 | C46: 0.72 | L46: 0.22 | M46: 0.85
A47: 0.225 | B47: 0.88 | C47: 0.75 | L47: 0.225 | M47: 0.88
A48: 0.23 | B48: 0.92 | C48: 0.78 | L48: 0.23 | M48: 0.92
A49: 0.235 | B49: 0.95 | C49: 0.81 | L49: 0.235 | M49: 0.95
A50: 0.24 | B50: 0.98 | C50: 0.83 | L50: 0.24 | M50: 0.98
A51: 0.245 | B51: 1.01 | C51: 0.86 | L51: 0.245 | M51: 1.01
A52: 0.25 | B52: 1.05 | C52: 0.89 | L52: 0.25 | M52: 1.05
A53: 0.255 | B53: 1.08 | C53: 0.92 | L53: 0.255 | M53: 1.08
...

Sheet Sounding Table_Calibrated
A2: SoundingTable Base | H2: Sounding Table - Calibration Points | L2: Calibration Points - Linearisation
A3: Level_m | B3: Volume_m3 | C3: Weight | D3: Correction_factor | F3: Revised Value = Volume_m3 + Correction_factor | H3: Level_m | I3: Corrected_Volume_m3 | J3: Entered_Correction_factor | L3: Level_m | M3: InterPoluted_Volume_m3 | AF3: Level_m | AG3: Volume_m3 | AH3: Volume_m3 | AI3: Correction_factor
A4: 0 | B4: 0.03 | C4: 0.02 | D4: =M4-B4 -> 0.01 | F4: =B4+D4 -> 0.04 | H4: 0 | I4: 0.04 | J4: 0.01 | L4: 0 | M4: =$I$4 + ((L4-$H$4)/$H$5-$H$4) * ($I$5 - $I$4) -> 0.04 | O4: Note: Calculation was done for first two correction factors | AF4: 0 | AG4: 0.03 | AH4: 0.04 | AI4: =AH4-AG4 -> 0.01
A5: 0.005 | B5: 0.03 | C5: 0.03 | D5: =M5-B5 -> 0.0195 | F5: =B5+D5 -> 0.0495 | H5: 0.1 | I5: 0.23 | J5: -0.03 | L5: 0.005 | M5: =$I$4 + ((L5-$H$4)/$H$5-$H$4) * ($I$5 - $I$4) -> 0.0495 | AF5: 0.1 | AG5: 0.26 | AH5: 0.23 | AI5: =AH5-AG5 -> -0.03
A6: 0.01 | B6: 0.04 | C6: 0.03 | D6: =M6-B6 -> 0.019 | F6: =B6+D6 -> 0.059 | H6: 0.2 | I6: 0.85 | J6: 0.12 | L6: 0.01 | M6: =$I$4 + ((L6-$H$4)/$H$5-$H$4) * ($I$5 - $I$4) -> 0.059 | AF6: 0.2 | AG6: 0.73 | AH6: 0.85 | AI6: =AH6-AG6 -> 0.12
A7: 0.015 | B7: 0.05 | C7: 0.04 | D7: =M7-B7 -> 0.0185 | F7: =B7+D7 -> 0.0685 | H7: 0.3 | I7: 1.15 | J7: -0.24 | L7: 0.015 | M7: =$I$4 + ((L7-$H$4)/$H$5-$H$4) * ($I$5 - $I$4) -> 0.0685 | AF7: 0.3 | AG7: 1.39 | AH7: 1.15 | AI7: =AH7-AG7 -> -0.24
A8: 0.02 | B8: 0.05 | C8: 0.05 | D8: =M8-B8 -> 0.028 | F8: =B8+D8 -> 0.078 | H8: 0.4 | I8: 2 | J8: -0.06 | L8: 0.02 | M8: =$I$4 + ((L8-$H$4)/$H$5-$H$4) * ($I$5 - $I$4) -> 0.078 | AF8: 0.4 | AG8: 2.06 | AH8: 2 | AI8: =AH8-AG8 -> -0.06
A9: 0.025 | B9: 0.06 | C9: 0.05 | D9: =M9-B9 -> 0.0275 | F9: =B9+D9 -> 0.0875 | H9: 0.5 | I9: 2.5 | J9: -0.24 | L9: 0.025 | M9: =$I$4 + ((L9-$H$4)/$H$5-$H$4) * ($I$5 - $I$4) -> 0.0875 | O9: Steps: | AF9: 0.5 | AG9: 2.74 | AH9: 2.5 | AI9: =AH9-AG9 -> -0.24
A10: 0.03 | B10: 0.07 | C10: 0.06 | D10: =M10-B10 -> 0.027 | F10: =B10+D10 -> 0.097 | H10: 0.6 | I10: 3.23 | J10: -0.18 | L10: 0.03 | M10: =$I$4 + ((L10-$H$4)/$H$5-$H$4) * ($I$5 - $I$4) -> 0.097 | O10: 1. Look up the correction factor’s volume and add it . | AF10: 0.6 | AG10: 3.41 | AH10: 3.23 | AI10: =AH10-AG10 -> -0.18
A11: 0.035 | B11: 0.08 | C11: 0.07 | D11: =M11-B11 -> 0.0265 | F11: =B11+D11 -> 0.1065 | H11: 0.7 | I11: 4.25 | J11: 0.16 | L11: 0.035 | M11: =$I$4 + ((L11-$H$4)/$H$5-$H$4) * ($I$5 - $I$4) -> 0.1065 | O11: 2.Perform linear calculation using the corrected volume and level, applying upto the next correction factor. | AF11: 0.7 | AG11: 4.09 | AH11: 4.25 | AI11: =AH11-AG11 -> 0.16
A12: 0.04 | B12: 0.09 | C12: 0.08 | D12: =M12-B12 -> 0.026 | F12: =B12+D12 -> 0.116 | H12: 0.8 | I12: 4.9 | J12: 0.14 | L12: 0.04 | M12: =$I$4 + ((L12-$H$4)/$H$5-$H$4) * ($I$5 - $I$4) -> 0.116 | AF12: 0.8 | AG12: 4.76 | AH12: 4.9 | AI12: =AH12-AG12 -> 0.14
A13: 0.045 | B13: 0.1 | C13: 0.09 | D13: =M13-B13 -> 0.0255 | F13: =B13+D13 -> 0.1255 | H13: 0.9 | I13: 5.25 | J13: -0.19 | L13: 0.045 | M13: =$I$4 + ((L13-$H$4)/$H$5-$H$4) * ($I$5 - $I$4) -> 0.1255 | O13: Formula: | AF13: 0.9 | AG13: 5.44 | AH13: 5.25 | AI13: =AH13-AG13 -> -0.19
A14: 0.05 | B14: 0.11 | C14: 0.1 | D14: =M14-B14 -> 0.025 | F14: =B14+D14 -> 0.135 | H14: 1 | I14: 6 | J14: -0.11 | L14: 0.05 | M14: =$I$4 + ((L14-$H$4)/$H$5-$H$4) * ($I$5 - $I$4) -> 0.135 | O14: V=V1+((L−L1)/(L2−L1))*(V2−V1) | AF14: 1 | AG14: 6.11 | AH14: 6 | AI14: =AH14-AG14 -> -0.11
A15: 0.055 | B15: 0.12 | C15: 0.11 | D15: =M15-B15 -> 0.0245 | F15: =B15+D15 -> 0.1445 | H15: 1.1 | I15: 6.5 | J15: -0.29 | L15: 0.055 | M15: =$I$4 + ((L15-$H$4)/$H$5-$H$4) * ($I$5 - $I$4) -> 0.1445 | O15: Linear Interpolution=CorrectedV1 + ((Level - Level1) / (Level2 - Level1)) * (CorrectedV2 - CorrectedV1) | AF15: 1.1 | AG15: 6.79 | AH15: 6.5 | AI15: =AH15-AG15 -> -0.29
A16: 0.06 | B16: 0.14 | C16: 0.12 | D16: =M16-B16 -> 0.014 | F16: =B16+D16 -> 0.154 | H16: 1.2 | I16: 7.35 | J16: -0.11 | L16: 0.06 | M16: =$I$4 + ((L16-$H$4)/$H$5-$H$4) * ($I$5 - $I$4) -> 0.154 | AF16: 1.2 | AG16: 7.46 | AH16: 7.35 | AI16: =AH16-AG16 -> -0.11
A17: 0.065 | B17: 0.15 | C17: 0.13 | D17: =M17-B17 -> 0.0135 | F17: =B17+D17 -> 0.1635 | H17: 1.3 | I17: 8 | J17: -0.14 | L17: 0.065 | M17: =$I$4 + ((L17-$H$4)/$H$5-$H$4) * ($I$5 - $I$4) -> 0.1635 | O17: CorrectedV1- Calibrated first volume range(I-coloumn) | AF17: 1.3 | AG17: 8.14 | AH17: 8 | AI17: =AH17-AG17 -> -0.14
A18: 0.07 | B18: 0.16 | C18: 0.14 | D18: =M18-B18 -> 0.013 | F18: =B18+D18 -> 0.173 | H18: 1.4 | I18: 9 | J18: 0.19 | L18: 0.07 | M18: =$I$4 + ((L18-$H$4)/$H$5-$H$4) * ($I$5 - $I$4) -> 0.173 | O18: CorrectedV2- Calibrated next volume range(I-coloumn) | AF18: 1.4 | AG18: 8.81 | AH18: 9 | AI18: =AH18-AG18 -> 0.19
A19: 0.075 | B19: 0.18 | C19: 0.15 | D19: =M19-B19 -> 0.0025 | F19: =B19+D19 -> 0.1825 | H19: 1.5 | I19: 9.5 | J19: 0.01 | L19: 0.075 | M19: =$I$4 + ((L19-$H$4)/$H$5-$H$4) * ($I$5 - $I$4) -> 0.1825 | O19: Level-current level(L-coloumn) | AF19: 1.5 | AG19: 9.49 | AH19: 9.5 | AI19: =AH19-AG19 -> 0.01
A20: 0.08 | B20: 0.19 | C20: 0.16 | D20: =M20-B20 -> 0.002 | F20: =B20+D20 -> 0.192 | H20: 1.6 | I20: 10 | J20: -0.16 | L20: 0.08 | M20: =$I$4 + ((L20-$H$4)/$H$5-$H$4) * ($I$5 - $I$4) -> 0.192 | O20: Level1-frist range in H coloumn | AF20: 1.6 | AG20: 10.16 | AH20: 10 | AI20: =AH20-AG20 -> -0.16
A21: 0.085 | B21: 0.21 | C21: 0.18 | D21: =M21-B21 -> -0.0085 | F21: =B21+D21 -> 0.2015 | H21: 1.7 | I21: 10.95 | J21: 0.11 | L21: 0.085 | M21: =$I$4 + ((L21-$H$4)/$H$5-$H$4) * ($I$5 - $I$4) -> 0.2015 | O21: Level2-Next range in H coloumn | AF21: 1.7 | AG21: 10.84 | AH21: 10.95 | AI21: =AH21-AG21 -> 0.11
A22: 0.09 | B22: 0.22 | C22: 0.19 | D22: =M22-B22 -> -0.009 | F22: =B22+D22 -> 0.211 | H22: 1.8 | I22: 11.8 | J22: 0.29 | L22: 0.09 | M22: =$I$4 + ((L22-$H$4)/$H$5-$H$4) * ($I$5 - $I$4) -> 0.211 | AF22: 1.8 | AG22: 11.51 | AH22: 11.8 | AI22: =AH22-AG22 -> 0.29
A23: 0.095 | B23: 0.24 | C23: 0.2 | D23: =M23-B23 -> -0.0195 | F23: =B23+D23 -> 0.2205 | H23: 1.9 | I23: 12 | J23: -0.19 | L23: 0.095 | M23: =$I$4 + ((L23-$H$4)/$H$5-$H$4) * ($I$5 - $I$4) -> 0.2205 | AF23: 1.9 | AG23: 12.19 | AH23: 12 | AI23: =AH23-AG23 -> -0.19
A24: 0.1 | B24: 0.26 | C24: 0.22 | D24: =M24-B24 -> -0.03 | F24: =B24+D24 -> 0.23 | H24: 2 | I24: 12.5 | J24: -0.36 | L24: 0.1 | M24: =$I$4 + ((L24-$H$4)/$H$5-$H$4) * ($I$5 - $I$4) -> 0.23 | AF24: 2 | AG24: 12.86 | AH24: 12.5 | AI24: =AH24-AG24 -> -0.36
A25: 0.105 | B25: 0.28 | C25: 0.23 | H25: 2.03 | I25: 13 | J25: -0.06 | L25: 0.105 | O25: Legends: | AF25: 2.03 | AG25: 13.06 | AH25: 13 | AI25: =AH25-AG25 -> -0.06
A26: 0.11 | B26: 0.29 | C26: 0.25 | L26: 0.11 | O26: Entered_Correction_factors
A27: 0.115 | B27: 0.31 | C27: 0.27 | L27: 0.115 | O27: Calculated Interpolution values
A28: 0.12 | B28: 0.33 | C28: 0.28 | L28: 0.12 | O28: used for Linear Interpolution calculation
A29: 0.125 | B29: 0.35 | C29: 0.3 | L29: 0.125 | O29: Calculated Correction_factors
A30: 0.13 | B30: 0.37 | C30: 0.32 | L30: 0.13
A31: 0.135 | B31: 0.4 | C31: 0.34 | L31: 0.135
A32: 0.14 | B32: 0.42 | C32: 0.35 | L32: 0.14
A33: 0.145 | B33: 0.44 | C33: 0.37 | L33: 0.145
A34: 0.15 | B34: 0.46 | C34: 0.39 | L34: 0.15
A35: 0.155 | B35: 0.49 | C35: 0.41 | L35: 0.155
A36: 0.16 | B36: 0.51 | C36: 0.43 | L36: 0.16
A37: 0.165 | B37: 0.54 | C37: 0.46 | L37: 0.165
A38: 0.17 | B38: 0.56 | C38: 0.48 | L38: 0.17
A39: 0.175 | B39: 0.59 | C39: 0.5 | L39: 0.175
A40: 0.18 | B40: 0.61 | C40: 0.52 | L40: 0.18
A41: 0.185 | B41: 0.64 | C41: 0.55 | L41: 0.185
...
